Workbook
Name \0: #REF!
Name \a: #REF!
Name \aq: #REF!
Name \b: #REF!
Name \C: #REF!
Name \e: #REF!
Name \f: #REF!
Name \l: #REF!
Name \p: #REF!
Name \q: #REF!
Name \S: #REF!
Name \w: #REF!
Name \x: #REF!
Name \z: #N/A
Name _________________________________________________________________________________________b111121: #REF!
Name _________________________________________________________________________________________Ki1: #REF!
Name _________________________________________________________________________________________Ki2: #REF!
Name ________________________________________________________________________________________b111121: #REF!
Name ________________________________________________________________________________________Ki1: #REF!
Name ________________________________________________________________________________________Ki2: #REF!
Name _______________________________________________________________________________________b111121: #REF!
Name _______________________________________________________________________________________Ki1: #REF!
Name _______________________________________________________________________________________Ki2: #REF!
Name _______________________________________________________________________________________MAN1: #REF!
Name _______________________________________________________________________________________PB1: #REF!
Name _______________________________________________________________________________________TB2: #REF!
Name ______________________________________________________________________________________b111121: #REF!
Name ______________________________________________________________________________________Ki1: #REF!
Name ______________________________________________________________________________________Ki2: #REF!
Name ______________________________________________________________________________________MAN1: #REF!
Name ______________________________________________________________________________________PB1: #REF!
Name ______________________________________________________________________________________TB2: #REF!
Name _____________________________________________________________________________________b111121: #REF!
Name _____________________________________________________________________________________Ki1: #REF!
Name _____________________________________________________________________________________Ki2: #REF!
Name _____________________________________________________________________________________MAN1: #REF!
Name _____________________________________________________________________________________PB1: #REF!
Name _____________________________________________________________________________________TB2: #REF!
Name ____________________________________________________________________________________b111121: #REF!
Name ____________________________________________________________________________________Ki1: #REF!
Name ____________________________________________________________________________________Ki2: #REF!
Name ____________________________________________________________________________________MAN1: #REF!
Name ____________________________________________________________________________________PB1: #REF!
Name ____________________________________________________________________________________TB2: #REF!
Name ___________________________________________________________________________________b111121: #REF!
Name ___________________________________________________________________________________Ki1: #REF!
Name ___________________________________________________________________________________Ki2: #REF!
Name ___________________________________________________________________________________MAN1: #REF!
Name ___________________________________________________________________________________PB1: #REF!
Name ___________________________________________________________________________________TB2: #REF!
Name __________________________________________________________________________________b111121: #REF!
Name __________________________________________________________________________________Ki1: #REF!
Name __________________________________________________________________________________Ki2: #REF!
Name __________________________________________________________________________________MAN1: #REF!
Name __________________________________________________________________________________PB1: #REF!
Name __________________________________________________________________________________TB2: #REF!
Name _________________________________________________________________________________b111121: #REF!
Name _________________________________________________________________________________Ki1: #REF!
Name _________________________________________________________________________________Ki2: #REF!
Name _________________________________________________________________________________MAN1: #REF!

Sheet MAIN SUMMARY
B1: PHOTON - DLF CYBER CITY - HYDERABAD UNPRICED BOQ FOR INTERIOR AND MEP SERVICES
A3: BOQ SUMMARY
A4: S.NO | B4: PACKAGE | C4: AMOUNT( Rs)
A5: 1 | B5: INTERIOR WORKS | C5: =INTERIOR!G224 -> 20485551
A6: 2 | B6: RESTROOM FINISHES | C6: ='REST ROOM'!H32 -> 2511037.1
A7: 3 | B7: HVAC | C7: ='HVAC SUMMARY'!E10 -> 4698772.7
A8: 4 | B8: LT ELECTRICAL WORKS | C8: =ELEC_Summary!C39 -> 8595785.9
A9: 5 | B9: UPS
A10: 6 | B10: FIRE SAFETY AND SECURITY SYSTEMS BOQ | C10: ='FAS AND PA SUMMARY'!E14 -> 6358576.8
A11: 7 | B11: PHE SYSTEM BOQ | C11: =PHE!C5 -> 2134411
B12: TOTAL ( EXCLUDING TAXES) | C12: =SUM(C5:C11) -> 44784135
B13: BOCW @1% extra.
B14: The above BOQ does not included the following
A15: 1 | B15: cost of power and water during construction
A16: 2 | B16: Cost of PCC screed
A17: 3 | B17: cost of ISP, EPABX & Network active components
A18: 4 | B18: cost of white goods and office equipment's , Kitchen equipements and appliances , Plants and planter boxes
A19: 5 | B19: cost of AV equipment's
A20: 6 | B20: cost of power feeders , AHU, Rising main, VFD, IBMS system and base building infrastructure works

Sheet INTERIOR
A1: INTERIOR WORKS
A2: S.N0 | B2: Description of Item | C2: Specification | D2: Unit | E2: Total Qty | F2: Rate ( Supply+ Installation) | G2: Amount | H2: JLL Remarks
C4: Notes:
C5: Below mentioned points are under Civil & Interior works vendors scope
C6: All unnecessary holes, gaps, openings in the walls, gyp ceiling / partitions, floor etc to be filled / closed by joinery vendor. AHU room and external wall / shaft to be sealed with Aerocon wall. All external wall gap to be sealed with Fire stop / Acoustical sealant as specified.
C7: Joinery vendor to be responsible for labor toilets – maintenance etc. (for all the agencies).
C8: Scrapping of flooring & cleaning the floor before carpet installation. (Floor to be wet mobbed & handed over to carpet installation team).
C9: Cleaning / painting of lobby & other builder areas which will be used by the agencies while execution.
C10: Touch up & finishing of all the existing doors which are handed over by builder while taking the possession.
C11: All unnecessary holes, gaps, openings in the walls, gyp ceiling / partitions, floor etc to be filled / closed by joinery vendor (in the AHU rooms, unnecessary opening of walls to be closed only by building wall & not using any other material like ply or gyp board etc).
C12: Housekeeping ( Including housekeeping on daily basis) to be part of your quotation and will not be paid extra. General housekeeping for all other packages to be in joinery vendor scope which is indicated as separate item in BOQ
C13: Electrical vendor to provide temp lighting for fitout execution period . Power junction boxes to be placed at every 10 meter distance with all safety norms recommended by the base builder /PM.
C14: Note: *Vendors are requested to visit the site and quote accordingly. *Vendor shall follow safety, barricading needs to be done as per PM /Architect instruction *Site should be left clean and broom finish once work complete and every day morning before 10AM *vendors are requested to visit the site and check the availability of water, power, service lift, debris dumping yard, lighting and quote accordingly for the works mentioned below. *Vendor to the check the work timings permitted from client / builder. *Quoted rates should includes shifting, lifting, loading, unloading of materials. *Quoted rates should includes scaffolding at all heights.
C15: All the Basic price exclusive of all the taxes,transportation charges and wastage etc..
... C26: The project timeline for completion is 75 days from the date of project kick-off. The vendor must provide a milestone schedule and resource details specific to this project.
A29: A | B29: DEMOLITION WORKS
A30: 1 | B30: Breaking of wall ( Toilet Work and other services) | C30: Demolition of existing wall of any thickness inclusive of removal of existing brick wall , Aerocon wall , RCC lintels, RCC slabs, cleaning etc, & disposal of debris from building premises as per base builders guidelines. ( Existing rest room walls and counter , internal plumbing lines to be removed and debris to be cleared from the building premises) | D30: Sqm | E30: 220 | F30: 371 | G30: =IFERROR(E30*F30,0) -> 81620
A31: 2 | B31: Breaking of Existing d base PCC screed | C31: Breaking of existing Tile Flooring and base PCC screed ( up to 70-90mm Avg depth) and cleaning & disposal of debris from building premises as per base builders guidelines | D31: Sqm | E31: 250 | F31: 318 | G31: =IFERROR(E31*F31,0) -> 79500
A32: 3 | B32: Floor grinding | C32: Existing screed floor (where the undulations are more than 3-5mm) to be levelled with floor grinding machine as per site condition. Cost inclusive of cleaning the screed floor and clear debris from building premises as per PM directions after completion of work. | D32: sqm | E32: 100 | F32: 265 | G32: =IFERROR(E32*F32,0) -> 26500
A33: B | B33: ANTI TERMITE TREATMENT | F33: 0 | G33: =IFERROR(E33*F33,0) -> 0
A34: 1 | B34: Anti Termite Treatment | C34: Providing Pest control and Anti-termite treatment by appointing a specialised agency as per the specifications mentioned by the Bureau of Indian Standards and Agencies specifications (whichever is higher), for General Civil, Plumbing,/ Drainage and timber/ Carpentry works, Gypsum related work, including a 5-year guarantee under suitable undertaking on stamp paper etc, complete as directed. (Mode of measurement to be on carpet-area of floor and not the area of surface treated.) . three rounds of pest control in all areas, first round to be executed at the time of commencement of fit-out, balance to be executed during fit-out as per PM directions. | D34: Sqm | E34: 1275 | F34: 90.1 | G34: =IFERROR(E34*F34,0) -> 114877.5
F35: 0 | G35: =IFERROR(E35*F35,0) -> 0
A36: C | B36: CIVIL & WET WORKS | F36: 0 | G36: =IFERROR(E36*F36,0) -> 0
A37: 1 | B37: POP punning | C37: Providing and applying POP punning to walls of avg. 12mm - 15mm thickness and above to line level and plumb; required punning to be undertaken and completed in workman-like manner, to ensure desired finishing standards, as per approval(s) of the Architects. The final finish should be of a uniform and neat finish to the satisfaction of the Architect. | D37: Sqm | E37: =300 -> 300 | F37: 445.2 | G37: =IFERROR(E37*F37,0) -> 133560
A38: 2 | B38: PCC Screed - 70-80 mm thk | C38: Providing and laying PCC screed up to 70-80 mm avg Ht. of cement concrete ratio 1:3:6 (1unit cement, 3units- sand, 6units- course aggregate) in necessary level & slope, finished smoothly with 6-8mm thick. Layer of cement mortar of 1:1 mix (1unit- cement, 1unit- Fine screened sand) in power float finish with proper curing by logging water or sprinkling water or by laying wet gunny bags etc complete as directed. The cost includes Scaffolding all ancillary works as per base builders guidelines and as per site condition . | D38: Sqm | E38: 250 | F38: 795 | G38: =IFERROR(E38*F38,0) -> 198750
A39: 3 | B39: Cement plaster ( To correct External wall undulations) | C39: Providing and applying in one coat, 15mm thick plaster on internal surface of RCC / brick/block walls/ column in cement mortar 1:4, finished rough to take on POP punning. Rate shall include for scaffolding, making grooves, sills, pattas, curing, surface preparation before the application of plaster, providing galvanized chicken mesh to a width of 150 mm at the junctions of masonry and concrete works including tying in position by using suitable nails / clamps / screws and as directed etc. complete at all levels. The contractor shall make good the grooves, pockets etc. after the scaffolding is removed.. Make - Coromandel, L&T, Steel : TATA/ Jindal | D39: Sqm | E39: 100 | F39: 424 | G39: =IFERROR(E39*F39,0) -> 42400
A40: 4 | B40: 150mm thick Aerocon wall - Intermediate wall - Future Exp Area & Handwash, Plate wash,server room,Battery ups room,Cafeteria | C40: Providing & constructing of AAC wall set in adhesive 5mm to 10mm thick / 1:4 cement mortar, inclusive of single coat rough Cement Plaster on both sides of wall in 1:4 , with minimum 2 nos of 6mm dia MS bars (Including tie bars) with 75mm height cement concrete at every 5 courses. Rates to include scaffolding, curing, RCC Lintel, at all heights, constructed to true line & plumb, etc., complete as per the Architect's instructions. Note : Rate should be inclusive of Masking for fixtures & wooden frames. Wall to be built till true ceiling. Rate to include RCC lintel (Lintel overlap length - 300mm to 450mm both ends -length vary based on door size) at necessary heights for doors (Lintel - door bottom & top). Curing of blocks to be done till the satisfactory of PM's. At the junction of RCC structure & block walls, Necessary Wall hacking and cement slurry to be considered on existing structure joints overlap and finished with POP Punning. * Density - 550-700 kg/m3 * Compressive strength - 30 - 50 kg/cm2 * Fire Resistant - Highly fire resistant & able to withstand the standard fire for 240minutes under load. * ISI Mark & Norms - products have ISI (BIS) norms and marking and are conforming to Indian standards. Blocks are conforming to IS 2185 (part 3). * Sound Absorption - Sound absorbency of air borne sound for 3" & 4" walls is 38 to 40 db. Mode of Measurement : Wall will be measured on one side (i.e. Total length of the wall x height of wall {LxH}) | D40: Sqm | E40: =58*4 -> 232 | F40: 2597 | G40: =IFERROR(E40*F40,0) -> 602504
A41: 5 | B41: 100mm thick Aerocon wall - AHU Opening closure | C41: Providing & constructing of AAC wall set in adhesive 5mm to 10mm thick / 1:4 cement mortar, inclusive of single coat rough Cement Plaster on both sides of wall in 1:4 , with minimum 2 nos of 6mm dia MS bars (Including tie bars) with 75mm height cement concrete at every 5 courses. Rates to include scaffolding, curing, RCC Lintel, at all heights, constructed to true line & plumb, etc., complete as per the Architect's instructions. Note : Rate should be inclusive of Masking for fixtures & wooden frames. Wall to be built till true ceiling. Rate to include RCC lintel (Lintel overlap length - 300mm to 450mm both ends -length vary based on door size) at necessary heights for doors (Lintel - door bottom & top). Curing of blocks to be done till the satisfactory of PM's. At the junction of RCC structure & block walls, Necessary Wall hacking and cement slurry to be considered on existing structure joints overlap and finished with POP Punning. * Density - 550-700 kg/m3 * Compressive strength - 30 - 50 kg/cm2 * Fire Resistant - Highly fire resistant & able to withstand the standard fire for 240minutes under load. * ISI Mark & Norms - products have ISI (BIS) norms and marking and are conforming to Indian standards. Blocks are conforming to IS 2185 (part 3). * Sound Absorption - Sound absorbency of air borne sound for 3" & 4" walls is 38 to 40 db. Mode of Measurement : Wall will be measured on one side (i.e. Total length of the wall x height of wall {LxH}) | D41: Sqm | E41: 10 | F41: 2491 | G41: =IFERROR(E41*F41,0) -> 24910
A42: 6 | B42: Self Levelling | C42: Providing and laying of Ardex Commercial levelling cementitious flooring system Surface preparation: Removing all existing weak, un sound CC floor to reach the strong substrate, cleaning the floor area to make it free from all contaminants and complete as per manufacturer's specification. Providing and applying Ardex P 51 primer to the base substrate and allow it to dry completely. Providing and mixing of CL 11, commercial levelling compound consisting of high quality special cement and selected fillers, with water at rate of 5.5-6 Ltr for 25 Kg bag of CL 11, installing at required 3mm to 5mm thickness using suitable pin rake trowel and notch trowel, finally rolling the surface with spike roller and allowed to dry completely, installing vinyl /LVT flooring as per client's requirement, etc and complete as per manufacturer's specification. [ The properties shall confirm to:- Bulk density of powder: Approx. 1.3 kg / Ltr; Weight of fresh mortar: Approx. 2.0 kg / Ltr; Working time: Approx. 25 min; Flow life: Approx. 15 min; Initial set (Vicat): Approx. 40 min; Final set (Vicat) Approx. 1 hr; Ball impact hardness: 6.5mm; Scratch hardness: 1.6mm; Compressive strength: 20 N / Up to 3mm thk self levelling) | D42: Sqm | E42: 925 | F42: 477 | G42: =IFERROR(E42*F42,0) -> 441225
A43: D | B43: PARTITION & PANELLING | F43: 0 | G43: =IFERROR(E43*F43,0) -> 0 | I43: Final Measurement Qty | J43: Amount
A44: 1 | B44: Double glazed partition - up to 2400mm - Black color frame -Double glass- Sandwitch Glass | C44: Supply and fixing of Double glazed Partition - GD-105W+ Geze Dela Partition system - Black Anodized: Supply and Fixing of Geze Dela System GD-105W+ i.e., Double glazed modular system consist of Aluminium section of 30x105x1.5mm thick. All sections duly anodised up to 20–25 microns with 6063-T6 grade and required accessories i.e. glass to glass aluminium I/H sections, T section & 90 degree L sections & Glass packing to adjust the floor level. Ceiling profile, Floor profile and wall profile are 30 mm visible face and 105 mm wide with 11.52mm laminated glass + Air Gap + 11.52 mm laminated glass with insertion of Thermoplastic gasket to adhere the glass firm & airtight. Make: GEZE / Eq from JEB / Alloy | D44: Sqm | E44: =40*2.6 -> 104 | F44: 14808.2 | G44: =IFERROR(E44*F44,0) -> 1540052.8 | H44: Alloy Make considered | I44: 92.18 | J44: =I44*F44 -> 1365019.9
A45: 2 | B45: Full Ht. Single Glazed partitions - 2400 mm Height . - - Black colour frame | C45: Supply and installation of full height Single glazed partitions formed out of the following components. Fabricating and Fixing of Glazed Partition with Anodized Aluminium Partition System of 100 x 25/35 mm thick section type placed both horizontally & vertically, Finish of frame : Anodized aluminium with black powder coated as approved by architect. The glazing to be formed out of 10 mm thick toughened glass as per details. The glass to be butt jointed with 2 to 3 mm edge chamfer & edge polishing all around. The butt joint of the glass shall have the aluminium profile & sealed using 3M glass to glass joint tape. Rate to include necessary 12mm thick MDF support finished with approved paint at the junction of false ceiling/solid partition & glass partition as per details .Rate to include 12mm thk MDF strip between modular frame and gypsum partitions all round and finished with paint as per details . Only visible glass surface will be measured and paid for this item. Fixing to be followed as per manufacturers specification. The height of glass partition to be 2.6mtr . Make : GEZE /JEB / Alloy | D45: QRO-Sqm | F45: 6148 | G45: =IFERROR(E45*F45,0) -> 0 | H45: Alloy Make considered
A46: 3 | B46: Partition above Glass partition - 100 mm thk (2+2 Layers Gypsum) - Gyproc - 100mm (50mmX25 mm Alu. Box section- 12.5mm thk plain board . Outer skin - 13 mm thk rigiroc Gypsum Board - 2+2 skin ( 100 mm thk) | C46: Providing and fixing baffle partition above glazed partition and doors of overall thickness of 100mm with the following components. The Frame work consist of 25mm x 50mm x 1.2mm thick extruded Aluminium box section framework at spacing not exceeding 600mm both ways (horizontal and vertical). The framework shall be secured at floor, structural ceiling and sill/ Lintel level. Framework to be secured to Floor / Walls / Columns / Ceiling / Beams using 75mm metal screws and dowels as per details.The framework to be cladded inner layer 12.5 mm thk plain Gypsum board & Outer layer of 13mm thick RIGIROC Gypboard, conforming to IS 2095 Part 1:2011, having flexural strength – {Longitudinal > 500N & transverse > 180N} on either side of the framing on either side of the framing from False ceiling level up to true ceiling level in line and level screw fixed with 25mm & 35mm drywall screws at 300mm centre to centre (150mm C/C at Floor & True Ceiling level) with staggered joints to avoid through joints. The board shall be jointed and finished to have a flushed look by filling and finishing with proprietary supplied jointing tape & compound and Two coats of Dry wall coat as per manufacturer's specification. Joints to be sand papered to achieve a smooth and seamless finish as per architects approval. Gypsum surface to be fully treated and finished to receive the Paint . Includes Putty , Primer etc., As an acoustic requirement, the cavity between the Boards shall be placed with 50mm thick Rock wool of density 48kg/m3, blanket wrapped in RP tissue suitably affixed to partition framework using where necessary GI binding wire, duct tape as indicated in the drawing. Note : Rock Wool with RP.Tissue packing of size 600 x 600mm/ 1200X600 mm . The junction of the partition with masonry & all penetration through the partition has to be treated with Hilti CP 606/ Hilti CP 620 / Pyroplex 2WT3IOP fire and acoustic sealant. Note : Aluminium section / plywood support to be provided wherever required for extra support to fix aluminium skirting, doors, storages, writing boards, glass boards, soft boards, projection screens, LED, paintings, artifacts, display, light fixtures, niches, glazed partition, mirrors, reader panel as per architects instructions. Meeting rooms with LED mounts to have sufficient aluminium & plywood support to house the bracket / mount. The partition cost should include Borer / Antitermite treatment for salwood and plywood as per architects instructions and dwg. Also cost to include making cut outs for AC ducts / Electrical works / Security systems / other services works / Switches / Sockets etc., complete. Wherever required by contractors and on completion of ducting, wiring work, the opening / cutouts to be closed as not to allow any transmission of sound or air as per architect's / PM's instructions. Partition installation to be done as per Gyproc/USG standard Installation process . One 4 pax meeting room full mock up to be done and approved by gyproc/USG Technical team /PM/ Architect . | D46: Sqm | E46: =68*1.6 -> 108.8 | F46: 4108.3639 | G46: =IFERROR(E46*F46,0) -> 446989.99
A47: 4 | B47: 100 mm thk Double Skin Gypsum partition - Make: Gyproc - Inner skin - 12.5mm thk plain board . Outer skin - 13 mm thk rigiroc Gypsum Board - 2+2 skin ( 100 mm thk) | C47: Providing and fixing 100 mm thk double skin gypsum partition - FRAME WORK: To be formed of cold rolled GI studs of size 48mm (0.5mm thk having one flange of 34mm and another flange of 36mm made of GI Steel), placed at 600mm centre to centre fixed onto the floor channels. The GI channels of size 50mm x 0.55mm (section thick) to be fixed on the floor to hold GI studs as per details. Also to have an additional 19mm thick ply supports /rigid salwood frame (wherever required) as spacer at the false ceiling level and as sub frames for doors and glazed openings as per details or as per architects instruction. INSULATION: As an acoustic requirement, contractor to affix 50mm thick Rock Wool of density 48 kg/m3 wrapped in RP tissues suitably affixed to partition framework using necessary GI binding wire, duct tape as indicated in the drawing. CLADDING: The inner layer to be finished with 12.5 mm thk tapered edge gypsum board (IS-2095 Part 1:2011) and the outer layer 13mm thk RIGIROC Gypsum board (from Finished floor level to till false ceiling) of in line and level screw fixed with 25mm drywall flat head screws @ 300mm c/c with staggered joints to avoid through joints and finished with proprietary supplied jointing tape and compound as per manufacturer's specification. Joints to be sand papered to achieve a smooth and seamless finish. Care must be taken that the plasterboards are raised 3mm from the floor and in this gap, chauking compound is injected, for successive layers and similarly for the ceiling channel/sections. Gypsum partition to be installed as per manufacturer specifications.To have 12mm ply to receive the skirting but Rate NOT to include skirting. The junction between partition & ceiling to be provided with 'L' shaped channel as per details. Finishes: Gypsum surface till the false ceiling on both sides - 2 coats of primer to be applied onto the gypsum surface. Surface to be smoothened using chalk putty as directed. Surfaces are then sandpapered to achieve a smooth surface and primer to be applied to receive paint . Make: GYPROC/USG . Note : Rock Wool with RP.Tissue packing of size 600 x 600mm / 600X1200 mm . The junction of the partition with masonry & all penetration through the partition has to be treated with Hilti CP 606/ Hilti CP 620 / Pyroplex 2WT3IOP fire and acoustic sealant. Gypsum surface to be fully treated and finished to receive the Paint . Includes Putty , Primer etc., Note : Aluminium section / plywood support to be provided wherever required for extra support to fix aluminium skirting, doors, storages, writing boards, glass boards, soft boards, projection screens, LED, LED, paintings, artifacts, display, light fixtures, niches, glazed partition, mirrors, reader panel as per architects instructions. Meeting rooms with LED mounts to have sufficient aluminium & plywood support to house the bracket / mount. The partition cost should include Borer / Ant termite treatment for salwood and plywood as per architects instructions and dwg. Also cost to include making cut outs for AC ducts / Electrical works / Security systems / other services works / Switches / Sockets etc., complete. Wherever required by contractors and on completion of ducting, wiring work, the opening / cut-outs to be closed as not to allow any transmission of sound or air as per architect's / PM's instructions. Partition installation to be done as per USG/ Gyproc standard Installation process . One mock up to be done and approved by gyproc/USG Technical team /PM/ Architect . Gypsum surface to be fully treated and finished to receive the Paint . One 4 pax meeting room full mock up to be done and approved by gyproc/USG Technical team /PM/ Architect . | D47: Sqm | E47: =70*4 -> 280 | F47: 3720.2012 | G47: =IFERROR(E47*F47,0) -> 1041656.3
A48: 5 | B48: Single Skin Gypsum partition - Store room - Plain Gypsum Board - 75mm thk (1+1) | C48: Providing and fixing 75 mm thk single skin gypsum partition - FRAME WORK: To be formed of cold rolled GI studs of size 48mm (0.5mm thk having one flange of 34mm and another flange of 36mm made of GI Steel), placed at 600mm centre to centre fixed onto the floor channels. The GI channels of size 50mm x 0.55mm (section thick) to be fixed on the floor to hold GI studs as per details. Also to have an additional 19mm thick ply supports /rigid salwood frame (wherever required) as spacer at the false ceiling level and as sub frames for doors and glazed openings as per details or as per architects instruction. INSULATION:As an acoustic requirement, contractor to affix 50mm thick glass wool of density 48kg/m3 wrapped in RP tissues suitably affixed to partition framework using necessary GI binding wire, duct tape as indicated in the drawing.. CLADDING: The framework to be cladded on both sides with single layer (from Finished floor level to till false ceiling) of 12.5 mm thk tapered edge gypsum board (IS-2095 Part 1:2011) in line and level screw fixed with 25mm drywall flat head screws @ 300mm c/c with staggered joints to avoid through joints and finished with proprietary supplied jointing tape and compound as per manufacturer's specification. Joints to be sand papered to achieve a smooth and seamless finish. Care must be taken that the plasterboards are raised 3mm from the floor and in this gap, chauking compound is injected, for successive layers and similarly for the ceiling channel/sections. Gypsum partition to be installed as per manufacturer specifications.To have 12mm ply to receive the skirting but Rate NOT to include skirting. The junction between partition & ceiling to be provided with 'L' shaped channel as per details. FInishes: Gypsum surface till the false ceiling on both sides - 2 coats of primer to be applied onto the gypsum surface. Surface to be smoothened using chalk putty as directed. Surfaces are then sandpapered to achieve a smooth surface and cost to include 3 coats of Plastic emulsion Paint of approved shade to be applied. Make: GYPROC / USG . Note : Glass Wool with RP.Tissue packing of size 600 x 600mm. The junction of the partition with masonry & all penetration through the partition has to be treated with Hilti CP 606/Pyroplex 2WT3IOP fire and acoustic sealant. Note : Aluminium section / plywood support to be provided wherever required for extra support to fix aluminum skirting, doors, storages, writing boards, glass boards, soft boards, projection screens, LCD, Plasma, paintings, artifacts, display, light fixtures, niches, glazed partition, mirrors, reader panel as per architects instructions. Meeting rooms with LCD mounts to have sufficient aluminium & plywood support to house the bracket / mount. The partition cost should include Borer / Antitermite treatment for salwood and plywood as per architects instructions and dwg. Also cost to include making cut outs for AC ducts / Electrical works / Security systems / other services works / Switches / Sockets etc., complete. Wherever required by contractors and on completion of ducting, wiring work, the opening / cutouts to be closed as not to allow any transmission of sound or air as per architect's / PM's instructions. | D48: Sqm | E48: 25 | F48: 2161.3888 | G48: =IFERROR(E48*F48,0) -> 54034.72
A49: 6 | B49: Fire rated Gypsum partition ( Server , UPS and Battery Room) | C49: 122mm thick - C-stud partition which includes double layer of tapered edge 12.5mm thick - Fireline of size 1219x2438mm is screw fixed to C-stud. 70x0.5mm C-stud placed at 610mm c/c in 72x0.5mm Floor and Ceiling channel. Floor & Ceiling channel is anchored to the floor & true ceiling using - Rawl plug Ø8x45mm /Hilti X-GN20MX anchor fasteners at 600mm c/c in zig zag manner. Floor channel to be wrapped with 70μ Self Adhesive LDPE moisture barrier film to further improve corrosion resistance performance. 12.5mm thick - Fireline board strip of 72mm width is placed between ceiling channel and RCC ceiling slab when deflection is more than 10mm & fire rating is more than 30min. Noggin channel of 70x0.5mm width has to be provided at the horizontal joints of the two boards. First layer of - boards to be screw fixed with - Drywall screws of 25mm at minimum spacing of 600mm at centre and 600mm at periphery. Second layer to be screw fixed - Drywall screws of 35mm at minimum spacing of 300mm at centre and 300mm at periphery. 50mm glasswool slab of density 24kg/m³ shall be placed in metal framework. Glasswool holding clip should be used to hold glasswool slab in its position. Finally square and tapered edges of the boards are to be jointed and finished so as to have a flush look which includes filling and finishing with - Pro-Fill Jointing compound, - Joint Paper tape or fibre tape. The junction of the partition with masonry & all penetration through the partition has to be treated with Hilti/Pyroplex fire and acoustic sealant. All other detailing and specifications to be followed as per approved shop drawing. Cost Includes 12mm thk bison board backing inside server room to mount Power panels and Distribution boards. The junction of the partition with masonry & all penetration through the partition has to be treated with Hilti CP 606/Pyroplex 2WT3IOP fire and acoustic sealant. Make- Gyproc/ USG - 2 Hr fire line board and sections . All detailing and specifications to be followed as per approved drawing of Gyproc. Contractors should strictly adehre manufacturers guidelines for installation . After completion of work , Manufacturers technical team to inspect the installation and provide certificate for 2HR fire rating . Make: GYPROC / Eq. USG | D49: Sqm | E49: 10 | F49: 4134.2414 | G49: =IFERROR(E49*F49,0) -> 41342.414
A50: 7 | B50: Aluminium frame work - 50X50 mm - Only Frame work | C50: Providing and fixing partitions consisting of 50mm x 25mm x 1.2mm Aluminum sections framework with all necessary reinforcements required of wood/aluminum, at spacing not exceeding 600mm bothways. ( horizontal & vertical) Partition framework to be provided with bracing/angular supports & secured to structural ceiling & nearest structural member using 75mm galvanized metal screws & wooden dowels. Cost to include provision of cut outs for duct and cable tray routing above ceiling at locations indicated on the drawings or as instructed by the architects. | D50: Sqm | E50: 25 | F50: 1296.9565 | G50: =IFERROR(E50*F50,0) -> 32423.913 | H50: Aluminium frame work - 50X25 mm as per the query response.
A51: 8 | B51: Aluminium frame work - 25X25 mm - Only Frame work | C51: Providing and fixing partitions consisting of 25mm x 25mm x 1.2mm Aluminum sections framework with all necessary reinforcements required of wood/aluminum, at spacing not exceeding 600mm bothways. ( horizontal & vertical) Partition framework to be provided with bracing/angular supports & secured to structural ceiling & nearest structural member using 75mm galvanized metal screws & wooden dowels. Cost to include provision of cut outs for duct and cable tray routing above ceiling at locations indicated on the drawings or as instructed by the architects. | D51: Sqm | E51: 10 | F51: 1102.8751 | G51: =IFERROR(E51*F51,0) -> 11028.751
A52: 9 | B52: One skin Gypsum on Aluminium/ GI frame work | C52: Installaing one skin gypsum board on Aluminium / GI frame work . Only Gypsum board supply and installation cost to be quoted (Excluding Frame work) | D52: Sqm | E52: 10 | F52: 410.65155 | G52: =IFERROR(E52*F52,0) -> 4106.5155
A53: 10 | B53: Two skins Gypsum on Aluminium/ GI frame work | C53: Installaing two skins gypsum board on Aluminium / GI frame work . Only Gypsum board supply and installation cost to be quoted (Excluding Frame work) | D53: Sqm | E53: 10 | F53: 821.3031 | G53: =IFERROR(E53*F53,0) -> 8213.031
...

Sheet REST ROOM
A1: RESTROOM BOQ
A2: S.NO | B2: Item | C2: Specification | D2: Make | E2: Unit | F2: Total Qty | G2: Rate | H2: Amount | I2: JLL Remarks
A4: 1 | B4: 150mm thick Aerocon wall | C4: Making 150mm thick wall of Aerocon Block in 1:4 cement mortar, inclusive of 12 mm thick single coat rough Cement Plaster on both sides of wall in 1:6 Cement Mortar,with 2 nos. of 8 mm diameter steel reinforcement in every 4 layer & 2 nos. of hoop iron strips 25mm x 1.6mm, painted with anti-corrosive paint, RCC Lintel at 2400 mm Ht, properly bent and bonded at the end, inclusive of shuttering, scaffolding, Raking of joints and proper curing etc complete. The joints between the RCC and masonry will have hold fasts @ 600mm c/c, with joints finished in chicken mesh 20 gauge and finished with cement plaster | E4: Sqm | F4: 85 | G4: 2597 | H4: =F4*G4 -> 220745
A5: 2 | B5: 100mm thick Aerocon wall | C5: Making 100mm thick wall of Aerocon Block in 1:4 cement mortar, inclusive of 12 mm thick single coat rough Cement Plaster on both sides of wall in 1:6 Cement Mortar,with 2 nos. of 8 mm diameter steel reinforcement in every 4 layer & 2 nos. of hoop iron strips 25mm x 1.6mm, painted with anti-corrosive paint, RCC Lintel at 2400 mm Ht, properly bent and bonded at the end, inclusive of shuttering, scaffolding, Raking of joints and proper curing etc complete. The joints between the RCC and masonry will have hold fasts @ 600mm c/c, with joints finished in chicken mesh 20 gauge and finished with cement plaster | E5: Sqm | F5: 10 | G5: 2491 | H5: =F5*G5 -> 24910
A6: 3 | B6: Aerocon light weight blocks filling | C6: Aerocon Light weight blocks filling up to 200-300 mm depth. cost inclusive of Providing top layer in 50 mm thk Grano Flooring.to receive tile floor | E6: Sqm | F6: 50 | G6: 3074 | H6: =F6*G6 -> 153700
A7: 4 | B7: Cinder filling | C7: Providing and laying of raised floor 300mm deep with necessary cinder with 25-50mm thk 1:2:4 grade PCC concrete, curing 2 days and then finishing the surface with 10mm thk of 1:6 mortar to proper level and slope. Rate to include necessary steps and ramp as per architects instructions. | E7: Sqm | F7: 20 | G7: 2597 | H7: =F7*G7 -> 51940
A8: 5 | B8: Water proofing | C8: Providing, supplying, mixing and applying two coats of ready-to-use two-component acrylic polymer, modified cement base, flexible water-proofing slurry or approved equivalent to a thickness of 2 mm over the bottom and sides of the slab / sunken slab. Waterproofing to extend upto 600 on the preiphery walls. Cost to include checking of waterproofing for 48 hours with 300mm high water logged floor.Method Statement of water proofing to be submitted before execution. | E8: Sqm | F8: 100 | G8: 954 | H8: =F8*G8 -> 95400
A9: 6 | B9: 150mm thick Ledge wall | C9: Making 150mm thick ledge wall of Aerocon Block in 1:4 cement mortar, inclusive of 12 mm thick single coat rough Cement Plaster in 1:6 Cement Mortar | E9: Rmt | F9: 20 | G9: 2650 | H9: =IFERROR(F9*G9,0) -> 53000
A10: 7 | B10: Vitrified tiles flooring 1200x600 MM for toilet | C10: Supply and laying of 1200X600 mm Vitrified tiles laid over adequate thickness of cement mortar 1:4(1cement:4 coarse sand) with 3mm thk spacers , saint gobain weber epoxy grout , finished neat, allowing for necessary spacing for rubbing down the edges at corners.. Includes protection with foam sheets with 2 layer of plastic cover after installation, deep cleaning before handover . Actual laid area shall be measured and paid for this item. Make- Kajaria / Asian. Basic price - 900/ sqm . Make Epoxy Grout- Saintgobain Weber. | D10: Tile: Kajaria / Johnson / Somany/ Asian ; Epoxy Grout, Adhesive - Weber-Saintgobain | E10: Sqm | F10: 100 | G10: 1940.436 | H10: =IFERROR(F10*G10,0) -> 194043.6
A11: 8 | B11: Vitrified tiles wall dado 600 x 600 / 300X600 | C11: Supply and laying of 600X600mm / 300X600 mm Vitrified tiles laid over adequate thickness of cement mortar 1:4(1cement:4 coarse sand) with 2mm thk spacers filled with epoxy grout . Cost includes corner beading and ancillary works , Actual laid area shall be measured and paid for this item. Make- Kajaria / Asian. Basic price - 900/ sqm . Make Epoxy Grout- Saintgobain Weber. | D11: Tile: Kajaria / Johnson / Somany/ Asian ; Epoxy Grout,Adhesive - Weber-Saintgobain | E11: Sqm | F11: =61*2.6 -> 158.6 | G11: 1940.436 | H11: =IFERROR(F11*G11,0) -> 307753.15
A12: 9 | B12: Cement plastering | C12: Existing wall to be finished with 12 mm thick cement plaster in CM 1:5 to walls Internal in single coat at all levels to correct line to a maximum of 50 mm and level including scaffolding, if any, and rounding off or champhering of corners, cleaning of surface, raking out joints, chiseling the undulated surface wherever necessary and curing, etc., all materials and labour complete in all respects including all lead, lift and descent and as directed | D12: Make- Ultratech / Ramco | E12: Sqm | F12: =61*2.6 -> 158.6 | G12: 477 | H12: =IFERROR(F12*G12,0) -> 75652.2
A13: 10 | B13: Granite Ledge | C13: Providing and fixing thresholds of 18mm thick pre-polished granite slab of approved shade fixed along the doors (it shall be provided flush with finished edges of the wall as per the wall thickness) on a bed of average 35mm thick cement mortar 1:4, as per detailed design the width 100 to 300mm and as directed and shall be provided flush with adjoining flooring levels, with all exposed edges finished as per details and with machine mirror polishing. (Basic Cost of Granite - Rs. 250/- per sq.ft) All complete as per instruction & satisfaction of Project Managers. | E13: Rmt | F13: 30 | G13: 3029.3125 | H13: =IFERROR(F13*G13,0) -> 90879.376
A14: 11 | B14: Washbasin counter - Granite finish | C14: 600 mm wide counter for wash basin in 19mm thk granite finish . Powder coated MS angle frame support to be fixed to the brick wall and covered with 18mm thk PVC integral board. 19mm thk granite to be cladded over on PVC integral board as per the detail dwg . Includes 300 mm fascia below counter and 10 mm band above counter granite finish , c . Necessary cutouts to be taken in the counter to insert wash basin and trash bin . | E14: Rmt | F14: 10 | G14: 10070 | H14: =IFERROR(F14*G14,0) -> 100700
A15: 12 | B15: False Ceiling - Metal | C15: Providing & Fixing MetalWorks Lay in Perforated metal ceiling System consisting of 600mm x 600mm Lay in tiles of pre coated galvanized steel in 0.5 mm thickness in approved color with perforation of 2.5mm dia, 5.5mm square pitch & open area of 16% with Freudenberg Soundtex/ Owens Corning Acoustimax S acoustical fleece on the back of the tile to be laid on grid systems with black silhouette 15mm wide T - section flanges. The tiles should have Humidity Resistance (RH) of 95%, NRC of 0.70 (Soundtex C1986SP of Freudenberg or Acoustimax S of Owens Corning fleece inlay or as per detail drawing), Fire Performance A2-s1.d0 in module size of 600 X 600 mm, suitable for Green Building application, with Recycled content of 25%. Cross tees shall have staked XL clips that ensure a minimum pull off strength of 100 Kgs/joint. The Tile & Grid system used together should carry a 10 year warrantee. The rate should be inclusive of necessary cutouts for Services etc. Load test as per manufactures to be carried out on site and test certificate to be provided.. Make- Fameline / Daiken. Basic price - 1800 /Sqm | D15: Daiken / Fameline | E15: Sqm | F15: 100 | G15: 2332 | H15: =IFERROR(F15*G15,0) -> 233200
A16: 13 | B16: Gypsum Ceiling | C16: Providing & Fixing of 12.5mm thk MR Gypsum board false ceiling to G.I. framing in perfect level. Necessary offsets and grooves to be provided at the junction of ceiling & walls/columns/partitions etc., Cut out for light fittings A/C grills etc. Rate to include providing & fixing of necessary G.I./wooden/MS frame supports for the above fixtures & additional suspenders & the ceiling in AC duct area as per architects instructions. G.I.frame to consist of proprietary supplied frames & as per manufacturers recommendations suspended from dash fasteners anchored to structural slab by means of G.I.angles. Gypsum board fixed with proprietary supplied fixing devices & finished. The joint between the sheets of plasterboard are to be covered with jointing paper tape and flushed with UB 888 (all purposes jointing compound) to provide a smooth durable and professional finish. Suspension points and clips shall be able to take a minimum safe load of 50 kgs. including making grooves at the junction of ceiling & walls/columns/partitions etc. Cut-outs for light fittings, A/C grills etc. to be left wherever necessary. the ceiling profile shall be as per Architects instructions. The rate shall be inclusive of preparing the surface, providing and applying 2 coats of proper putty and primer and 3 coats of paint, roller applied Acrylic emulsion paint of approved quality / colour to Architect's approval. All complete including return air slits etc. & A/C boxing wherever indicated. Note : Marking of Electrical , Fire Alarm & Air-conditioning & co-ordination with marking of fixtures to be considered. Gypsum ceiling to be installed as per IGL specifications. Note : Marking of Electrical , Fire Alarm & Air-conditioning & co-ordination with marking of fixtures to be considered. Note: Measurement to be along the horizontal surface of the ceiling and the verticals (till 200mm ht) shall be included in arriving at cost. Rate quoted to include vertical drops (till 200mm ht) and all cut-outs required for light fixtures, smoke detectors and other services cut-outs complete as directed by Architect. Verticals above 200mm ht will be measured separately. Rate to include cove lighting provision as per detail drawings | D16: USG / Gyproc | E16: Sqm | F16: 20 | G16: 1462.8 | H16: =IFERROR(F16*G16,0) -> 29256
A17: 14 | B17: Rest room Signage | C17: 6 x 9 inch Restroom Sign in Stainless Steel Metal, Engraved, Door / Wall Mount Sign, Silver and Black | D17: SS | E17: Nos | F17: 5 | G17: 1537 | H17: =IFERROR(F17*G17,0) -> 7685
A18: 15 | B18: Rest room Cubicles- Top hung cubicle - Merino / Greenlam /Stylam | C18: Providing & fixing SS Top Hung module 12mm HPL partition with SS 304 Hardware & SS finish sections. standard dimension 1050/1200mm (Width) x1650 mm (L) X 2000mm Ht . -Thickness of Compact Laminate :12 mm Thick Size of Cubicle : Pl refer Rest room Floor plan and submit shop dwg Door Size for Cubicle : 600mm Bottom Gap - 100 mm . Cost includes taking necessary supports for the top hung cubicle from true ceiling . | D18: Greenlam Air collction Wind / Eq in Merino / I Space | E18: Nos | F18: 10 | G18: 30531.611 | H18: =IFERROR(F18*G18,0) -> 305316.11 | I18: Make - Merino & Model - ZMS SS Series considered.
A19: 16 | B19: HD - 1200 x 2400mm (For Handicap Toilet Entrance) - Sliding Door | C19: Providing and constructing single shutter sliding door of 1200 mm size made of 38mm thick blockboard of approved make with Haffle / Hettich sliding track profile , Shutter to be finished in 1mm thk glossy laminate of approved shade, inclusive of all hardwares , Recessed SS handle , Vaccant / Engaged lock , door floor stoppr as per detailed drawing complete. (Make Fittings - Haffle / Hettich) . Blockboard : Prestige/Greenply / Century , Make of Laminate - Merino, Greenlam, Century.Basic Price - Rs- 750 / sqm . Cost includes 200X400 mm powder coated ventilation grill and laminated pelmet above sliding track . | D19: (Make Fittings - Haffle / Hettich) . Blockboard : Prestige/Greenply / Century , Make of Laminate - Merino, Greenlam, Century.Basic Price - Rs- 750 / sqm | E19: Nos | F19: 1 | G19: 59413 | H19: =IFERROR(F19*G19,0) -> 59413
A20: 17 | B20: 1200 x 2400 mm Aluminium Door Frame & Flush door with Full Ht (Toilet) | C20: Door Jamb : 100mm X 25mm Proprietary anodised aluminium section with black powder coated finish.. Black anodised Action : Single Swing . 100X25X2400 mm Ht . Door frame to be grouted to the PCC Floor with suitable Brackets as per manufacturers specification. Black anodised Shutter Construction : 32mm thk Flush door in laminate finish with vision panel as per detail dwg . Cost includes 200X400 mm powder coated ventilation grill . Make - Greenply / Century Hinge Type : 4 Nos Hinges . Dorma / Gaze 5" Flush suitable to style shutter Lockset : Dorma 952 Narrow style lock / GEZE 8134002 Door Handle : D Type offset handle 450 mm high . Black anodised Door Closer: - Dorma TS 71 Door Closer / Eq GEZE Door Stopper : Dorma / Geze Door frame make: Alloy / Geze / JEB Glass- Saint Gobain . | D20: GEZE / Alloy / JEB . Glass - Saintgobain | E20: Nos | F20: 1 | G20: 53689 | H20: =IFERROR(F20*G20,0) -> 53689 | I20: Door Frame - Alloy make considered. Door Hardwares - Geze make considered.
A21: 18 | B21: 900 x 2100 mm Aluminium Door Frame & Flush door with Full Ht Restrooms) | C21: Door Jamb : 100mm X 25mm Proprietary anodised aluminium section with black powder coated finish.. Black anodised Action : Single Swing . 100X25X2400 mm Ht . Door frame to be grouted to the PCC Floor with suitable Brackets as per manufacturers specification. Black anodised Shutter Construction : 32mm thk Flush door in laminate finish with vision panel as per detail dwg . Cost includes 200X400 mm powder coated ventilation grill . Make - Greenply / Century Hinge Type : 4 Nos Hinges . Dorma / Gaze 5" Flush suitable to style shutter Lockset : Dorma 952 Narrow style lock / GEZE 8134002 Door Handle : D Type offset handle 450 mm high . Black anodised Door Closer: - Dorma TS 71 Door Closer / Eq GEZE Door Stopper : Dorma / geze Door frame make: Alloy / Geze / JEB Glass- Saint Gobain . | D21: GEZE / Alloy / JEB . Glass - Saintgobain | E21: Nos | F21: 2 | G21: 52629 | H21: =IFERROR(F21*G21,0) -> 105258 | I21: Door Frame - Alloy make considered. Door Hardwares - Geze make considered.
A22: 19 | B22: 750 x 2100 mm Aluminium Door Frame & Flush door with Full Ht (Shower room) | C22: Door Jamb : 100mm X 25mm Proprietary anodised aluminium section with black powder coated finish.. Black anodised Action : Single Swing . 100X25X2100 mm Ht . Door frame to be grouted to the PCC Floor with suitable Brackets as per manufacturers specification. Black anodised Shutter Construction : 32mm thk Flush door in laminate finish with vision panel as per detail dwg . Cost includes 200X400 mm powder coated ventilation grill . Make - Greenply / Century Hinge Type : 4 Nos Hinges . Dorma / Gaze 5" Flush suitable to style shutter Lockset : Dorma 952 Narrow style lock / GEZE 8134002 Door Handle : D Type offset handle 450 mm high . Black anodised Door Closer: - Dorma TS 71 Door Closer / Eq GEZE Door Stopper : Dorma / Geze Alloy / Geze / JEB Glass- Saint Gobain . | D22: GEZE / Alloy / JEB . Glass - Saintgobain | E22: Nos | F22: 1 | G22: 49916.364 | H22: =IFERROR(F22*G22,0) -> 49916.364 | I22: Door Frame - Alloy make considered. Door Hardwares - Geze make considered.
A23: 20 | B23: Shaft Door | C23: Providing and fixing Metal powder coated shaft door of size - 750 mm (W) X 1500 mm(Ht) . With Door frame , Recessed handle, Lock etc., | E23: QRO-Nos | G23: 25970
A24: 21 | B24: Luster paint | C24: Providing & applying of Luster painting for walls. Shall be applied with oil based primer coat after rubbing with sand paper onto the existing wall surface. Surface to be smoothened using chalk putty as directed. Uneven surfaces to be finished with 2 coats of chalk powder putty on the primer. Surfaces are then sandpapered to achieve a smooth surface and 3 coats of luster Paint of approved shade to be applied. The top coat should be 3 coats of 'Superfine' roller matt finish. The colour should be approved by Architect. Note : Rate should be inclusive of Masking for fixtures & wooden frames. | D24: Asian /Dulex | E24: Sqm | F24: 25 | G24: 318 | H24: =IFERROR(F24*G24,0) -> 7950
A25: 22 | B25: Mirror | C25: Providing and fixing of 6mm thick float mirror of approved make edge polished and without any defects, waves etc., shall be mounted on 12mm thick Marine ply (IS 710) backing with approved 3M Double sided tape / Adhesive as per details. To have aluminium U channel on Top and bottom to hold mirror as per details. Modiguard float mirror shall be considered. Rate including cove light provision and LED strip light all around mirror. | D25: Marine ply - Archid /Century . 3M | E25: Sqm | F25: 10 | G25: 4187 | H25: =IFERROR(F25*G25,0) -> 41870
A26: 23 | B26: Wash basin counter in corian finish | C26: 600 mm wide, 800 mm high wash basin counter made of 18mm thk WPC / PVC integral board , MS angle support finished with 12mm thk corian . Cost includes 100 mm high band above counter and 300 mm high front fascia as per detail dwg. Necessary cutout to be made in counter top to fix the counter sunk washbasins and sink . Basic price corian - 900/sqft . | E26: Sqm | F26: 3 | G26: 23850 | H26: =IFERROR(F26*G26,0) -> 71550
A27: 24 | B27: Vacant / non Vacant Knob | C27: Providing and fixing in position Vacant / non Vacant Indicator in toilets | D27: Kich | E27: Nos | F27: 2 | G27: 2650 | H27: =IFERROR(F27*G27,0) -> 5300
A28: 25 | B28: SS Grab bar | C28: Supply and Fixing of foldable type SS Grab bar for differently abled person toilet. | D28: Jaquar | E28: Nos | F28: 1 | G28: 1941.39 | H28: =IFERROR(F28*G28,0) -> 1941.39 | I28: Mode - AHS-CHR-1503 - As per the query response.
A29: 26 | B29: SS Grab bar | C29: Supply and Fixing of fixed type SS Grab bar for differently abled person toilet. | D29: Jaquar | E29: Nos | F29: 2 | G29: 8213.94 | H29: =IFERROR(F29*G29,0) -> 16427.88
A30: 27 | B30: Cockroach trap | C30: Providing and fixing in position of Cockroach trap | D30: Jaquar | E30: Nos | F30: 17 | G30: 2703 | H30: =F30*G30 -> 45951 | I30: Make : Chilli / ACO - As per the query response.
A31: 28 | B31: Janitor storage | C31: Providing and fixing janitor storage made of 18mm thk WPC / PVC integral board and finished with approved 1mm thk laminate . Height- 2100 mm . Depth- 450 mm. Cost includes adjustable vertical and horizontal shelves , Laminated shutters with finger groove handle , Lock etc., | D31: Greenply / Century | E31: sqm | F31: 7 | G31: 15370 | H31: =F31*G31 -> 107590
C32: TOTAL COST PER FLOOR ( EXCLUSIVE OF TAXES) | H32: =SUM(H4:H31) -> 2511037.1

Sheet HVAC SUMMARY
A1: HVAC BOQ SUMMARY
A2: S.No | B2: Description | C2: Supply Amount in INR | D2: Installation Amount in INR | E2: Total Amount INR
C3: PHASE-1 | D3: PHASE-1
A4: 1 | B4: HVAC LOW SIDE WORKS | C4: ='HVAC Lowside'!H179 -> 2237176 | D4: ='HVAC Lowside'!I179 -> 503202.1 | E4: =SUM(C4:D4) -> 2740378.1
A6: 2 | B6: VAV SYSTEM | C6: =VAV!H82 -> 58936 | D6: =VAV!I82 -> 7367 | E6: =SUM(C6:D6) -> 66303
A8: 3 | B8: VRF SYSTEM | C8: ='VRF SYSTEM'!H72 -> 1663767.6 | D8: ='VRF SYSTEM'!I72 -> 228324 | E8: =SUM(C8:D8) -> 1892091.6
B10: GRAND TOTAL (excluding taxes) | C10: =SUM(C4:C8) -> 3959879.6 | D10: =SUM(D4:D8) -> 738893.1 | E10: =SUM(E4:E8) -> 4698772.7

Sheet HVAC Lowside
A1: HVAC BOQ
A2: S.NO | B2: DESCRIPTION | C2: UNIT | D2: 1F | E2: TOTAL QTY | F2: IN INR | H2: IN INR
F3: SUPPLY RATE | G3: INSTALLATION RATE | H3: SUPPLY AMOUNT | I3: INSTALLATION AMOUNT
A5: A | B5: MECHANICAL SYSTEM
B6: AIR CONDITIONING WORKS
A8: 1 | B8: DOUBLE SKIN PLENUM for AHU's
B9: All Sheet metal cabinet type double skin air plenum section for air handling units supplied by Developer.The plenum shall be constructed using double-skinned acoustic panels with minimum 0.6 mm thick pre-coated GSS sheet for outer skin and & minimum 0.6 mm plain GSS sheet for inner skin of the unit. All the panels shall incorporate 50 mm thick PUF insulation sandwiched in between inner & outer skin.
A10: a | B10: Double skin Plenum with all supports suiting to site conditions. Plenum colour shall be similar to the existing AHU. | C10: Sqm | D10: 25 | E10: =SUM(D10:D10) -> 25 | F10: 3750 | G10: 400 | H10: =F10*E10 -> 93750 | I10: =G10*E10 -> 10000
F11: 0 | G11: 0
A12: 2 | B12: OUTDOOR MOUNT TYPE EXHAUST FAN' S | E12: =SUM(D12:D12) -> 0 | F12: 0 | G12: 0
B13: All fans shall have minimum 70% total efficiency. | F13: 0 | G13: 0
A14: a | B14: 600 Cfm - 35 mm external static double skin cabinet type Inline fan with all necessary supports. (café exhaust). Fan shall be provided with in built fan regulator. Outdoor Mount type | C14: Nos | D14: 1 | E14: =SUM(D14:D14) -> 1 | F14: 28090 | G14: 1590 | H14: =F14*E14 -> 28090 | I14: =G14*E14 -> 1590
A15: b | B15: 300 Cfm - 10 mm external static Double skin cabinet type explosion proof fan with all necessary supports. (Battery room exhaust). | C15: Nos | D15: 1 | E15: =SUM(D15:D15) -> 1 | F15: 20670 | G15: 1590 | H15: =F15*E15 -> 20670 | I15: =G15*E15 -> 1590
A16: c | B16: Supply fixing testing & commissioning of Hyderogen sensor with sequential timer suitable control panel to operate Battery room exhaust fan at regular 2hrs interval fan run 5.0 minutes and when increse the Hyderagen level above 1% switch ON the fan. Controller shall have bypass mode to switch ON / OFF manually with necessary control wiring. | C16: Nos | D16: 1 | E16: =SUM(D16:D16) -> 1 | F16: 58300 | G16: 1590 | H16: =F16*E16 -> 58300 | I16: =G16*E16 -> 1590
A17: d | B17: 500 Cfm -15mm external static cabinet type fresh air fan with prefilter & necessary supports Outdoor Mount type | C17: Nos | D17: 1 | E17: =SUM(D17:D17) -> 1 | F17: 20670 | G17: 1590 | H17: =F17*E17 -> 20670 | I17: =G17*E17 -> 1590
A18: e | B18: 1300 Cfm - 15 mm external static double skin cabinet type Inline fan with all necessary supports. (Toilet exhaust). Fan shall be provided with in built fan regulator. | C18: Nos | D18: 2 | E18: =SUM(D18:D18) -> 2 | F18: 58300 | G18: 2120 | H18: =F18*E18 -> 116600 | I18: =G18*E18 -> 4240
B19: Note: All Exhaust, Scrubber & Fresh air units should be compatible of third party BMS system integration & fire trippig should be consider in part Electrical vendor scope. HVAC vendor should be coordinate with Electrical & BMS vendor. | E19: =SUM(D19:D19) -> 0 | F19: 0 | G19: 0
E20: =SUM(D20:D20) -> 0 | F20: 0 | G20: 0
A21: 3 | B21: Sheet Metal Work using with Ductmate(TDF) Flanges for all sizes of the duct. Fabrication as per SMACNA Standards | E21: =SUM(D21:D21) -> 0 | F21: 0 | G21: 0
A22: 3.01 | B22: Galvanizing shall be Class VIII – light coating of zinc, nominal 120 gm / sqm surface area and Lock Forming Quality prime material alongwith mill test certificates. In addition, if deemed necessary, samples of raw material, selected at random by owner’s site representative shall be subject to approval and tested for thickness and zinc coating at contractor’s expense. | E22: =SUM(D22:D22) -> 0 | F22: 0 | G22: 0
B23: All duct construction and installation shall be in accordance with SMACNA standards. In addition ducts shall be factory fabricated utilizing the following machines to provide the requisite quality of ducts. | E23: =SUM(D23:D23) -> 0 | F23: 0 | G23: 0
B24: All ducts shall be fabricated and installed in workmanlike manner, conforming to relevant SMACNA codes. | E24: =SUM(D24:D24) -> 0 | F24: 0 | G24: 0
B25: Above 1000mm width duct bends Vanes to be considered every 300mm once cost inclusive of this items. | E25: =SUM(D25:D25) -> 0 | F25: 0 | G25: 0
B26: The Duct shall be supported with specified Supports at regular intervalas as mentioned in the technical specifications. (To ensure the air tightness, (All ducts shall be checked with third party Pressure test after completion of installation but before applying insulation) Report should be submit | E26: =SUM(D26:D26) -> 0 | F26: 0 | G26: 0
B27: Rectangular ducting | E27: =SUM(D27:D27) -> 0 | F27: 0 | G27: 0
B28: Sheet Metal Ducting As per Specification. Pressure 500 Pa | E28: =SUM(D28:D28) -> 0 | F28: 0 | G28: 0
A29: a | B29: 26 G Ducting with TDF flanges(0-550mm) | C29: Sqm | D29: 340 | E29: =SUM(D29:D29) -> 340 | F29: 750 | G29: 159 | H29: =F29*E29 -> 255000 | I29: =G29*E29 -> 54060
A30: b | B30: 24 G Ducting with TDF flanges(551-900mm) | C30: Sqm | D30: 150 | E30: =SUM(D30:D30) -> 150 | F30: 875 | G30: 159 | H30: =F30*E30 -> 131250 | I30: =G30*E30 -> 23850
A31: c | B31: 22 G Ducting with TDF flanges(901-1200mm) | C31: Sqm | D31: 75 | E31: =SUM(D31:D31) -> 75 | F31: 975 | G31: 159 | H31: =F31*E31 -> 73125 | I31: =G31*E31 -> 11925
A32: d | B32: 20 G Ducting with TDF flanges(1201-1600mm) | C32: Sqm | D32: 10 | E32: =SUM(D32:D32) -> 10 | F32: 1100 | G32: 159 | H32: =F32*E32 -> 11000 | I32: =G32*E32 -> 1590
A33: e | B33: 18 G Ducting with TDF flanges(1601 & above) | C33: Sqm | D33: 15 | E33: =SUM(D33:D33) -> 15 | F33: 1325 | G33: 159 | H33: =F33*E33 -> 19875 | I33: =G33*E33 -> 2385
A34: 3.02 | B34: Supply & applying of spray painting for exposed rectangular ducts(colour to confirmed by PMC/ARCH) -2 coats of primer to be considered as first level. Further based on finalized color one set of painting to be done. And final coat to be applied | C34: Sqmt | E34: =SUM(D34:D34) -> 0 | F34: 0 | G34: 0 | H34: =F34*E34 -> 0 | I34: =G34*E34 -> 0
F35: 0 | G35: 0
A36: 3.04 | B36: ELLIPTICAL DUCT | F36: 0 | G36: 0
